<sdf version='1.7'>
  <model name='wheeled_inverted_pendulum'>
    <link name='cmg'>
      <inertial>
        <pose>0 0 1.1105 0 -0 0</pose>
        <mass>2.84</mass>
        <inertia>
          <ixx>0.0698318</ixx>
          <ixy>-0.00116716</ixy>
          <ixz>2.70471e-06</ixz>
          <iyy>0.037866</iyy>
          <iyz>-1.23057e-05</iyz>
          <izz>0.0628381</izz>
        </inertia>
      </inertial>
      <collision name='cmg_fixed_joint_lump__frame_collision'>
        <pose>0 0 1.11464 1.5708 -0 0</pose>
        <geometry>
          <mesh>
            <scale>0.001 0.001 0.001</scale>
            <uri>model://cmg_robot_description/meshes/cmg_link.STL</uri>
          </mesh>
        </geometry>
        <surface>
          <friction>
            <torsional>
              <coefficient>1</coefficient>
              <use_patch_radius>1</use_patch_radius>
              <patch_radius>0.02</patch_radius>
            </torsional>
            <ode>
              <mu>1</mu>
              <mu2>1</mu2>
            </ode>
          </friction>
          <contact>
            <ode>
              <kp>1e+13</kp>
              <kd>1</kd>
              <max_vel>0.001</max_vel>
              <min_depth>1e-11</min_depth>
            </ode>
          </contact>
        </surface>
      </collision>
      <visual name='cmg_fixed_joint_lump__frame_visual'>
        <pose>0 0 1.11464 1.5708 -0 0</pose>
        <geometry>
          <mesh>
            <scale>0.001 0.001 0.001</scale>
            <uri>model://cmg_robot_description/meshes/cmg_link.STL</uri>
          </mesh>
        </geometry>
        <material>
          <script>
            <name>Gazebo/Grey</name>
            <uri>file://media/materials/scripts/gazebo.material</uri>
          </script>
        </material>
      </visual>
      <gravity>1</gravity>
      <gravity>1</gravity>
    </link>
    <joint name='Left_gimbal_joint' type='revolute'>
      <pose relative_to='cmg'>0 0.08 1.11689 0 -0 0</pose>
      <parent>cmg</parent>
      <child>Left_gimbal</child>
      <axis>
        <xyz>0 0 1</xyz>
        <limit>
          <lower>-0.6978</lower>
          <upper>0.6978</upper>
          <effort>100</effort>
          <velocity>100</velocity>
        </limit>
        <dynamics>
          <spring_reference>0</spring_reference>
          <spring_stiffness>0</spring_stiffness>
        </dynamics>
      </axis>
    </joint>
    <link name='Left_gimbal'>
      <pose relative_to='Left_gimbal_joint'>0 0 0 0 -0 0</pose>
      <inertial>
        <pose>0 0 0 0 -0 0</pose>
        <mass>1</mass>
        <inertia>
          <ixx>0.00377312</ixx>
          <ixy>0</ixy>
          <ixz>0</ixz>
          <iyy>0.00398967</iyy>
          <iyz>0</iyz>
          <izz>0.00061837</izz>
        </inertia>
      </inertial>
      <collision name='Left_gimbal_collision'>
        <pose>0 0 0 1.57 -0 0</pose>
        <geometry>
          <mesh>
            <scale>0.001 0.001 0.001</scale>
            <uri>model://cmg_robot_description/meshes/left_gimbal_link.STL</uri>
          </mesh>
        </geometry>
        <surface>
          <friction>
            <torsional>
              <coefficient>1</coefficient>
              <use_patch_radius>1</use_patch_radius>
              <patch_radius>0.02</patch_radius>
            </torsional>
            <ode>
              <mu>1</mu>
              <mu2>1</mu2>
            </ode>
          </friction>
          <contact>
            <ode>
              <kp>1e+13</kp>
              <kd>1</kd>
              <max_vel>0.001</max_vel>
              <min_depth>1e-11</min_depth>
            </ode>
          </contact>
        </surface>
      </collision>
      <visual name='Left_gimbal_visual'>
        <pose>0 0 0 1.57 -0 0</pose>
        <geometry>
          <mesh>
            <scale>0.001 0.001 0.001</scale>
            <uri>model://cmg_robot_description/meshes/left_gimbal_link.STL</uri>
          </mesh>
        </geometry>
        <material>
          <script>
            <name>Gazebo/Grey</name>
            <uri>file://media/materials/scripts/gazebo.material</uri>
          </script>
        </material>
      </visual>
      <gravity>1</gravity>
      <self_collide>1</self_collide>
      <gravity>1</gravity>
    </link>
    <joint name='Left_flywheel_joint' type='revolute'>
      <pose relative_to='Left_gimbal'>0 0 0 0 -0 0</pose>
      <parent>Left_gimbal</parent>
      <child>Left_flywheel</child>
      <axis>
        <xyz>0 1 0</xyz>
        <limit>
          <effort>100</effort>
          <velocity>1000</velocity>
          <lower>-1e+16</lower>
          <upper>1e+16</upper>
        </limit>
        <dynamics>
          <spring_reference>0</spring_reference>
          <spring_stiffness>0</spring_stiffness>
        </dynamics>
      </axis>
    </joint>
    <link name='Left_flywheel'>
      <pose relative_to='Left_flywheel_joint'>0 0 0 0 -0 0</pose>
      <inertial>
        <pose>0 0 0 0 -0 0</pose>
        <mass>4</mass>
        <inertia>
          <ixx>0.00595</ixx>
          <ixy>0</ixy>
          <ixz>0</ixz>
          <iyy>0.0113</iyy>
          <iyz>0</iyz>
          <izz>0.00595</izz>
        </inertia>
      </inertial>
      <collision name='Left_flywheel_collision'>
        <pose>0 0 0 0 -0 0</pose>
        <geometry>
          <mesh>
            <scale>0.001 0.001 0.001</scale>
            <uri>model://cmg_robot_description/meshes/left_flywheel_link.STL</uri>
          </mesh>
        </geometry>
        <surface>
          <contact>
            <ode>
              <kp>1e+13</kp>
              <kd>1</kd>
              <max_vel>0.001</max_vel>
              <min_depth>1e-11</min_depth>
            </ode>
          </contact>
          <friction>
            <ode>
              <mu>1</mu>
              <mu2>1</mu2>
            </ode>
          </friction>
        </surface>
      </collision>
      <visual name='Left_flywheel_visual'>
        <pose>0 0 0 0 -0 0</pose>
        <geometry>
          <mesh>
            <scale>0.001 0.001 0.001</scale>
            <uri>model://cmg_robot_description/meshes/left_flywheel_link.STL</uri>
          </mesh>
        </geometry>
        <material>
          <script>
            <name>Gazebo/White</name>
            <uri>file://media/materials/scripts/gazebo.material</uri>
          </script>
        </material>
      </visual>
      <gravity>1</gravity>
      <gravity>1</gravity>
    </link>
    <joint name='Right_gimbal_joint' type='revolute'>
      <pose relative_to='cmg'>0 -0.08 1.11689 0 -0 0</pose>
      <parent>cmg</parent>
      <child>Right_gimbal</child>
      <axis>
        <xyz>0 0 1</xyz>
        <limit>
          <lower>-0.6978</lower>
          <upper>0.6978</upper>
          <effort>100</effort>
          <velocity>100</velocity>
        </limit>
        <dynamics>
          <spring_reference>0</spring_reference>
          <spring_stiffness>0</spring_stiffness>
        </dynamics>
      </axis>
    </joint>
    <link name='Right_gimbal'>
      <pose relative_to='Right_gimbal_joint'>0 0 0 0 -0 0</pose>
      <inertial>
        <pose>0 0 0 0 -0 0</pose>
        <mass>1</mass>
        <inertia>
          <ixx>0.00377312</ixx>
          <ixy>0</ixy>
          <ixz>0</ixz>
          <iyy>0.00398967</iyy>
          <iyz>0</iyz>
          <izz>0.00061837</izz>
        </inertia>
      </inertial>
      <collision name='Right_gimbal_collision'>
        <pose>0 0 0 1.57 -0 0</pose>
        <geometry>
          <mesh>
            <scale>0.001 0.001 0.001</scale>
            <uri>model://cmg_robot_description/meshes/right_gimbal_link.STL</uri>
          </mesh>
        </geometry>
        <surface>
          <friction>
            <torsional>
              <coefficient>1</coefficient>
              <use_patch_radius>1</use_patch_radius>
              <patch_radius>0.02</patch_radius>
            </torsional>
            <ode>
              <mu>1</mu>
              <mu2>1</mu2>
            </ode>
          </friction>
          <contact>
            <ode>
              <kp>1e+13</kp>
              <kd>1</kd>
              <max_vel>0.001</max_vel>
              <min_depth>1e-11</min_depth>
            </ode>
          </contact>
        </surface>
      </collision>
      <visual name='Right_gimbal_visual'>
        <pose>0 0 0 1.57 -0 0</pose>
        <geometry>
          <mesh>
            <scale>0.001 0.001 0.001</scale>
            <uri>model://cmg_robot_description/meshes/right_gimbal_link.STL</uri>
          </mesh>
        </geometry>
        <material>
          <script>
            <name>Gazebo/Grey</name>
            <uri>file://media/materials/scripts/gazebo.material</uri>
          </script>
        </material>
      </visual>
      <gravity>1</gravity>
      <self_collide>1</self_collide>
      <gravity>1</gravity>
    </link>
    <joint name='Right_flywheel_joint' type='revolute'>
      <pose relative_to='Right_gimbal'>0 0 0 0 -0 0</pose>
      <parent>Right_gimbal</parent>
      <child>Right_flywheel</child>
      <axis>
        <xyz>0 1 0</xyz>
        <limit>
          <effort>100</effort>
          <velocity>1000</velocity>
          <lower>-1e+16</lower>
          <upper>1e+16</upper>
        </limit>
        <dynamics>
          <spring_reference>0</spring_reference>
          <spring_stiffness>0</spring_stiffness>
        </dynamics>
      </axis>
    </joint>
    <link name='Right_flywheel'>
      <pose relative_to='Right_flywheel_joint'>0 0 0 0 -0 0</pose>
      <inertial>
        <pose>0 0 0 0 -0 0</pose>
        <mass>4</mass>
        <inertia>
          <ixx>0.00595</ixx>
          <ixy>0</ixy>
          <ixz>0</ixz>
          <iyy>0.0113</iyy>
          <iyz>0</iyz>
          <izz>0.00595</izz>
        </inertia>
      </inertial>
      <collision name='Right_flywheel_collision'>
        <pose>0 0 0 0 -0 0</pose>
        <geometry>
          <mesh>
            <scale>0.001 0.001 0.001</scale>
            <uri>model://cmg_robot_description/meshes/right_flywheel_link.STL</uri>
          </mesh>
        </geometry>
        <surface>
          <contact>
            <ode>
              <kp>1e+13</kp>
              <kd>1</kd>
              <max_vel>0.001</max_vel>
              <min_depth>1e-11</min_depth>
            </ode>
          </contact>
          <friction>
            <ode>
              <mu>1</mu>
              <mu2>1</mu2>
            </ode>
          </friction>
        </surface>
      </collision>
      <visual name='Right_flywheel_visual'>
        <pose>0 0 0 0 -0 0</pose>
        <geometry>
          <mesh>
            <scale>0.001 0.001 0.001</scale>
            <uri>model://cmg_robot_description/meshes/right_flywheel_link.STL</uri>
          </mesh>
        </geometry>
        <material>
          <script>
            <name>Gazebo/White</name>
            <uri>file://media/materials/scripts/gazebo.material</uri>
          </script>
        </material>
      </visual>
      <gravity>1</gravity>
      <gravity>1</gravity>
    </link>
    <joint name='hip_roll_joint' type='revolute'>
      <pose relative_to='cmg'>0 0 0.893646 0 -0 0</pose>
      <parent>cmg</parent>
      <child>hip_link</child>
      <axis>
        <xyz>1 0 0</xyz>
        <limit>
          <lower>-0.785</lower>
          <upper>0.785</upper>
          <effort>100</effort>
          <velocity>1000</velocity>
        </limit>
        <dynamics>
          <spring_reference>0</spring_reference>
          <spring_stiffness>0</spring_stiffness>
        </dynamics>
      </axis>
    </joint>
    <link name='hip_link'>
      <pose relative_to='hip_roll_joint'>0 0 0 0 -0 0</pose>
      <inertial>
        <pose>0 0 -0.233968 3.14 -0 0</pose>
        <mass>9.117</mass>
        <inertia>
          <ixx>0.539767</ixx>
          <ixy>0.00083355</ixy>
          <ixz>0.000558229</ixz>
          <iyy>0.539306</iyy>
          <iyz>-0.000109232</iyz>
          <izz>0.0159448</izz>
        </inertia>
      </inertial>
      <collision name='hip_link_collision'>
        <pose>-0.042455 0 0 3.14 -0 0</pose>
        <geometry>
          <mesh>
            <scale>0.001 0.001 0.001</scale>
            <uri>model://cmg_robot_description/meshes/hip_link.STL</uri>
          </mesh>
        </geometry>
        <surface>
          <contact>
            <ode>
              <kp>1e+13</kp>
              <kd>1</kd>
              <max_vel>0.001</max_vel>
              <min_depth>1e-11</min_depth>
            </ode>
          </contact>
          <friction>
            <ode>
              <mu>1</mu>
              <mu2>1</mu2>
            </ode>
          </friction>
        </surface>
      </collision>
      <collision name='hip_link_fixed_joint_lump__hip_to_knee_link_collision_1'>
        <pose>0 0.0665 0 3.14 -0 0</pose>
        <geometry>
          <mesh>
            <scale>0.001 0.001 0.001</scale>
            <uri>model://cmg_robot_description/meshes/hip_to_knee_link.STL</uri>
          </mesh>
        </geometry>
        <surface>
          <contact>
            <ode>
              <kp>1e+13</kp>
              <kd>1</kd>
              <max_vel>0.001</max_vel>
              <min_depth>1e-11</min_depth>
            </ode>
          </contact>
          <friction>
            <ode>
              <mu>1</mu>
              <mu2>1</mu2>
            </ode>
          </friction>
        </surface>
      </collision>
      <collision name='hip_link_fixed_joint_lump__knee_ankle_link_collision_2'>
        <pose>4.5e-05 -0.059 -0.28 3.14 -0 0</pose>
        <geometry>
          <mesh>
            <scale>0.001 0.001 0.001</scale>
            <uri>model://cmg_robot_description/meshes/knee_to_ankle_pitch_link.STL</uri>
          </mesh>
        </geometry>
        <surface>
          <contact>
            <ode>
              <kp>1e+13</kp>
              <kd>1</kd>
              <max_vel>0.001</max_vel>
              <min_depth>1e-11</min_depth>
            </ode>
          </contact>
          <friction>
            <ode>
              <mu>1</mu>
              <mu2>1</mu2>
            </ode>
          </friction>
        </surface>
      </collision>
      <collision name='hip_link_fixed_joint_lump__ankle_pitch_roll_link_collision_3'>
        <pose>0 0 -0.559942 3.14 -0 0</pose>
        <geometry>
          <mesh>
            <scale>0.001 0.001 0.001</scale>
            <uri>model://cmg_robot_description/meshes/ankle_roll_link.STL</uri>
          </mesh>
        </geometry>
        <surface>
          <contact>
            <ode>
              <kp>1e+13</kp>
              <kd>1</kd>
              <max_vel>0.001</max_vel>
              <min_depth>1e-11</min_depth>
            </ode>
          </contact>
          <friction>
            <ode>
              <mu>1</mu>
              <mu2>1</mu2>
            </ode>
          </friction>
        </surface>
      </collision>
      <visual name='hip_link_visual'>
        <pose>-0.042455 0 0 3.14 -0 0</pose>
        <geometry>
          <mesh>
            <scale>0.001 0.001 0.001</scale>
            <uri>model://cmg_robot_description/meshes/hip_link.STL</uri>
          </mesh>
        </geometry>
        <material>
          <script>
            <name>Gazebo/Grey</name>
            <uri>file://media/materials/scripts/gazebo.material</uri>
          </script>
        </material>
      </visual>
      <visual name='hip_link_fixed_joint_lump__hip_to_knee_link_visual_1'>
        <pose>0 0.0665 0 3.14 -0 0</pose>
        <geometry>
          <mesh>
            <scale>0.001 0.001 0.001</scale>
            <uri>model://cmg_robot_description/meshes/hip_to_knee_link.STL</uri>
          </mesh>
        </geometry>
        <material>
          <script>
            <name>Gazebo/Grey</name>
            <uri>file://media/materials/scripts/gazebo.material</uri>
          </script>
        </material>
      </visual>
      <visual name='hip_link_fixed_joint_lump__knee_ankle_link_visual_2'>
        <pose>4.5e-05 -0.059 -0.28 3.14 -0 0</pose>
        <geometry>
          <mesh>
            <scale>0.001 0.001 0.001</scale>
            <uri>model://cmg_robot_description/meshes/knee_to_ankle_pitch_link.STL</uri>
          </mesh>
        </geometry>
        <material>
          <script>
            <name>Gazebo/Grey</name>
            <uri>file://media/materials/scripts/gazebo.material</uri>
          </script>
        </material>
      </visual>
      <visual name='hip_link_fixed_joint_lump__ankle_pitch_roll_link_visual_3'>
        <pose>0 0 -0.559942 3.14 -0 0</pose>
        <geometry>
          <mesh>
            <scale>0.001 0.001 0.001</scale>
            <uri>model://cmg_robot_description/meshes/ankle_roll_link.STL</uri>
          </mesh>
        </geometry>
        <material>
          <script>
            <name>Gazebo/Grey</name>
            <uri>file://media/materials/scripts/gazebo.material</uri>
          </script>
        </material>
      </visual>
      <gravity>1</gravity>
      <gravity>1</gravity>
      <gravity>1</gravity>
      <gravity>1</gravity>
      <gravity>1</gravity>
    </link>
    <joint name='ankle_roll_joint' type='revolute'>
      <pose relative_to='hip_link'>0 0 -0.559942 0 -0 0</pose>
      <parent>hip_link</parent>
      <child>ankle_roll_yaw_link</child>
      <axis>
        <xyz>1 0 0</xyz>
        <limit>
          <lower>-0.785</lower>
          <upper>0.785</upper>
          <effort>100</effort>
          <velocity>1000</velocity>
        </limit>
        <dynamics>
          <spring_reference>0</spring_reference>
          <spring_stiffness>0</spring_stiffness>
        </dynamics>
      </axis>
    </joint>
    <link name='ankle_roll_yaw_link'>
      <pose relative_to='ankle_roll_joint'>0 0 0 0 -0 0</pose>
      <inertial>
        <pose>0 0 -0.120465 1.57 -0 1.57</pose>
        <mass>2.083</mass>
        <inertia>
          <ixx>0.00824899</ixx>
          <ixy>5.56325e-06</ixy>
          <ixz>4.22191e-06</ixz>
          <iyy>0.00411693</iyy>
          <iyz>0.000395234</iyz>
          <izz>0.00729083</izz>
        </inertia>
      </inertial>
      <collision name='ankle_roll_yaw_link_collision'>
        <pose>0.0825 0 0 3.14 -0 0</pose>
        <geometry>
          <mesh>
            <scale>0.001 0.001 0.001</scale>
            <uri>model://cmg_robot_description/meshes/ankle_yaw_link.STL</uri>
          </mesh>
        </geometry>
        <surface>
          <contact>
            <ode>
              <kp>1e+13</kp>
              <kd>1</kd>
              <max_vel>0.001</max_vel>
              <min_depth>1e-11</min_depth>
            </ode>
          </contact>
          <friction>
            <ode>
              <mu>1</mu>
              <mu2>1</mu2>
            </ode>
          </friction>
        </surface>
      </collision>
      <collision name='ankle_roll_yaw_link_fixed_joint_lump__ankle_to_wheel_link_collision_1'>
        <pose>0 0 -0.2575 0 -0 0</pose>
        <geometry>
          <mesh>
            <scale>0.001 0.001 0.001</scale>
            <uri>model://cmg_robot_description/meshes/ankle_to_wheel_link.STL</uri>
          </mesh>
        </geometry>
        <surface>
          <contact>
            <ode>
              <kp>1e+13</kp>
              <kd>1</kd>
              <max_vel>0.001</max_vel>
              <min_depth>1e-11</min_depth>
            </ode>
          </contact>
          <friction>
            <ode>
              <mu>1</mu>
              <mu2>1</mu2>
            </ode>
          </friction>
        </surface>
      </collision>
      <visual name='ankle_roll_yaw_link_visual'>
        <pose>0.0825 0 0 3.14 -0 0</pose>
        <geometry>
          <mesh>
            <scale>0.001 0.001 0.001</scale>
            <uri>model://cmg_robot_description/meshes/ankle_yaw_link.STL</uri>
          </mesh>
        </geometry>
        <material>
          <script>
            <name>Gazebo/Grey</name>
            <uri>file://media/materials/scripts/gazebo.material</uri>
          </script>
        </material>
      </visual>
      <visual name='ankle_roll_yaw_link_fixed_joint_lump__ankle_to_wheel_link_visual_1'>
        <pose>0 0 -0.2575 0 -0 0</pose>
        <geometry>
          <mesh>
            <scale>0.001 0.001 0.001</scale>
            <uri>model://cmg_robot_description/meshes/ankle_to_wheel_link.STL</uri>
          </mesh>
        </geometry>
        <material>
          <script>
            <name>Gazebo/Grey</name>
            <uri>file://media/materials/scripts/gazebo.material</uri>
          </script>
        </material>
      </visual>
      <gravity>1</gravity>
      <gravity>1</gravity>
      <gravity>1</gravity>
    </link>
    <joint name='wheel_joint' type='revolute'>
      <pose relative_to='ankle_roll_yaw_link'>0 0 -0.2575 0 -0 0</pose>
      <parent>ankle_roll_yaw_link</parent>
      <child>wheel_link</child>
      <axis>
        <xyz>0 1 0</xyz>
        <limit>
          <effort>100</effort>
          <velocity>1000</velocity>
          <lower>-1e+16</lower>
          <upper>1e+16</upper>
        </limit>
        <dynamics>
          <spring_reference>0</spring_reference>
          <spring_stiffness>0</spring_stiffness>
        </dynamics>
      </axis>
    </joint>
    <link name='wheel_link'>
      <pose relative_to='wheel_joint'>0 0 0 0 -0 0</pose>
      <inertial>
        <pose>0 0 0 0 -0 0</pose>
        <mass>2</mass>
        <inertia>
          <ixx>0.00362337</ixx>
          <ixy>0</ixy>
          <ixz>0</ixz>
          <iyy>0.00651263</iyy>
          <iyz>0</iyz>
          <izz>0.00362337</izz>
        </inertia>
      </inertial>
      <collision name='wheel_link_collision'>
        <pose>0 0 0 0 -0 1.57</pose>
        <geometry>
          <mesh>
            <scale>0.001 0.001 0.001</scale>
            <uri>model://cmg_robot_description/meshes/wheel_link.STL</uri>
          </mesh>
        </geometry>
        <surface>
          <friction>
            <torsional>
              <coefficient>1</coefficient>
              <use_patch_radius>1</use_patch_radius>
              <patch_radius>0.02</patch_radius>
            </torsional>
            <ode>
              <mu>1</mu>
              <mu2>1</mu2>
            </ode>
          </friction>
          <contact>
            <ode>
              <kp>1e+13</kp>
              <kd>1</kd>
              <max_vel>0.001</max_vel>
              <min_depth>1e-11</min_depth>
            </ode>
          </contact>
        </surface>
      </collision>
      <visual name='wheel_link_visual'>
        <pose>0 0 0 0 -0 1.57</pose>
        <geometry>
          <mesh>
            <scale>0.001 0.001 0.001</scale>
            <uri>model://cmg_robot_description/meshes/wheel_link.STL</uri>
          </mesh>
        </geometry>
        <material>
          <script>
            <name>Gazebo/White</name>
            <uri>file://media/materials/scripts/gazebo.material</uri>
          </script>
        </material>
      </visual>
      <gravity>1</gravity>
      <gravity>1</gravity>
    </link>
    <static>0</static>
    <plugin name='gazebo_ros_control' filename='libgazebo_ros_control.so'>
      <controlPeriod>0.001</controlPeriod>
      <robotNamespace>/wheeled_inverted_pendulum</robotNamespace>
      <jointName>Left_flywheel_joint, Right_flywheel_joint, Left_gimbal_joint, Right_gimbal_joint, hip_roll_joint, hip_pitch_joint, knee_joint, ankle_pitch_joint, ankle_roll_joint, ankle_yaw_joint, wheel_joint</jointName>
      <robotSimType>gazebo_ros_control/DefaultRobotHWSim</robotSimType>
      <legacyModeNS>1</legacyModeNS>
    </plugin>
  </model>
</sdf>
