<?xml version="1.0"?>

<sdf version='1.7'>
  <model name='wheeled_inverted_pendulum'>
    <link name='cmg'>
      <inertial>
        <pose>0 0 1.1105 0 -0 0</pose>
        <mass>2.84</mass>
        <inertia>
          <ixx>0.0698318</ixx>
          <ixy>-0.00116716</ixy>
          <ixz>2.70471e-06</ixz>
          <iyy>0.037866</iyy>
          <iyz>-1.23057e-05</iyz>
          <izz>0.0628381</izz>
        </inertia>
      </inertial>

      <collision name='cmg_collision'>
        <pose>0 0 1.11464 1.5708 -0 0</pose>
        <geometry>
          <mesh>
            <scale>0.001 0.001 0.001</scale>
            <uri>model://cmg_robot_description/meshes/cmg_link.STL</uri>
          </mesh>
        </geometry>
        <surface>
          <friction>
            <torsional>
              <coefficient>1</coefficient>
              <use_patch_radius>1</use_patch_radius>
              <patch_radius>0.02</patch_radius>
            </torsional>
            <ode>
              <mu>1</mu>
              <mu2>1</mu2>
            </ode>
          </friction>
          <contact>
            <ode>
              <kp>1e+13</kp>
              <kd>1</kd>
              <max_vel>0.001</max_vel>
              <min_depth>1e-11</min_depth>
            </ode>
          </contact>
        </surface>
      </collision>

      <visual name='cmg_visual'>
        <pose>0 0 1.11464 1.5708 -0 0</pose>
        <geometry>
          <mesh>
            <scale>0.001 0.001 0.001</scale>
            <uri>model://cmg_robot_description/meshes/cmg_link.STL</uri>
          </mesh>
        </geometry>
        <material>
          <script>
            <name>Gazebo/Grey</name>
            <uri>file://media/materials/scripts/gazebo.material</uri>
          </script>
        </material>
      </visual>
      <gravity>1</gravity>
      <gravity>1</gravity>
    </link>

<!-- ######################################################################################### -->

    <joint name='Left_gimbal_joint' type='revolute'>
      <pose relative_to='cmg'>0 0.08 1.11689 0 -0 0</pose>
      <parent>cmg</parent>
      <child>Left_gimbal</child>
      <axis>
        <xyz>0 0 1</xyz>
        <limit>
          <lower>-0.6978</lower>
          <upper>0.6978</upper>
          <effort>100</effort>
        </limit>
        <!-- <use_parent_model_frame>1</use_parent_model_frame> -->
      </axis>
    </joint>

    <link name='Left_gimbal'>
      <pose relative_to='Left_gimbal_joint'>0 0 0 0 -0 0</pose>
      <inertial>
        <pose>0 0 0 0 -0 0</pose>
        <mass>1</mass>
        <inertia>
          <ixx>0.00377312</ixx>
          <ixy>0</ixy>
          <ixz>0</ixz>
          <iyy>0.00398967</iyy>
          <iyz>0</iyz>
          <izz>0.00061837</izz>
        </inertia>
      </inertial>

      <collision name='Left_gimbal_collision'>
        <pose>0 0 0 1.57 -0 0</pose>
        <geometry>
          <mesh>
            <scale>0.001 0.001 0.001</scale>
            <uri>model://cmg_robot_description/meshes/left_gimbal_link.STL</uri>
          </mesh>
        </geometry>
        <surface>
          <friction>
            <torsional>
              <coefficient>1</coefficient>
              <use_patch_radius>1</use_patch_radius>
              <patch_radius>0.02</patch_radius>
            </torsional>
            <ode>
              <mu>1</mu>
              <mu2>1</mu2>
            </ode>
          </friction>
          <contact>
            <ode>
              <kp>1e+13</kp>
              <kd>1</kd>
              <max_vel>0.001</max_vel>
              <min_depth>1e-11</min_depth>
            </ode>
          </contact>
        </surface>
      </collision>

      <visual name='Left_gimbal_visual'>
        <pose>0 0 0 1.57 -0 0</pose>
        <geometry>
          <mesh>
            <scale>0.001 0.001 0.001</scale>
            <uri>model://cmg_robot_description/meshes/left_gimbal_link.STL</uri>
          </mesh>
        </geometry>
        <material>
          <script>
            <name>Gazebo/Grey</name>
            <uri>file://media/materials/scripts/gazebo.material</uri>
          </script>
        </material>
      </visual>
      <gravity>1</gravity>
      <self_collide>1</self_collide>
      <gravity>1</gravity>
    </link>

<!-- ######################################################################################### -->

    <joint name='Left_flywheel_joint' type='revolute'>
      <pose relative_to='Left_gimbal'>0 0 0 0 -0 0</pose>
      <parent>Left_gimbal</parent>
      <child>Left_flywheel</child>
      <axis>
        <xyz>0 1 0</xyz>
        <limit>
          <effort>100</effort>
          <velocity>1000</velocity>
          <lower>-1e+16</lower>
          <upper>1e+16</upper>
        </limit>
        <dynamics>
          <spring_reference>0</spring_reference>
          <spring_stiffness>0</spring_stiffness>
        </dynamics>
      </axis>
    </joint>

    <link name='Left_flywheel'>
      <pose relative_to='Left_flywheel_joint'>0 0 0 0 -0 0</pose>
      <inertial>
        <pose>0 0 0 0 -0 0</pose>
        <mass>4</mass>
        <inertia>
          <ixx>0.00595</ixx>
          <ixy>0</ixy>
          <ixz>0</ixz>
          <iyy>0.0113</iyy>
          <iyz>0</iyz>
          <izz>0.00595</izz>
        </inertia>
      </inertial>

      <collision name='Left_flywheel_collision'>
        <pose>0 0 0 0 -0 0</pose>
        <geometry>
          <mesh>
            <scale>0.001 0.001 0.001</scale>
            <uri>model://cmg_robot_description/meshes/left_flywheel_link.STL</uri>
          </mesh>
        </geometry>
        <surface>
          <contact>
            <ode>
              <kp>1e+13</kp>
              <kd>1</kd>
              <max_vel>0.001</max_vel>
              <min_depth>1e-11</min_depth>
            </ode>
          </contact>
          <friction>
            <ode>
              <mu>1</mu>
              <mu2>1</mu2>
            </ode>
          </friction>
        </surface>
      </collision>

      <visual name='Left_flywheel_visual'>
        <pose>0 0 0 0 -0 0</pose>
        <geometry>
          <mesh>
            <scale>0.001 0.001 0.001</scale>
            <uri>model://cmg_robot_description/meshes/left_flywheel_link.STL</uri>
          </mesh>
        </geometry>
        <material>
          <script>
            <name>Gazebo/White</name>
            <uri>file://media/materials/scripts/gazebo.material</uri>
          </script>
        </material>
      </visual>
      <gravity>1</gravity>
      <gravity>1</gravity>
    </link>

<!-- ######################################################################################### -->

    <joint name='Right_gimbal_joint' type='revolute'>
      <pose relative_to='cmg'>0 -0.08 1.11689 0 -0 0</pose>
      <parent>cmg</parent>
      <child>Right_gimbal</child>
      <axis>
        <xyz>0 0 1</xyz>
        <limit>
          <lower>-0.6978</lower>
          <upper>0.6978</upper>
          <effort>100</effort>
          <velocity>100</velocity>
        </limit>
        <dynamics>
          <spring_reference>0</spring_reference>
          <spring_stiffness>0</spring_stiffness>
        </dynamics>
      </axis>
    </joint>

    <link name='Right_gimbal'>
      <pose relative_to='Right_gimbal_joint'>0 0 0 0 -0 0</pose>
      <inertial>
        <pose>0 0 0 0 -0 0</pose>
        <mass>1</mass>
        <inertia>
          <ixx>0.00377312</ixx>
          <ixy>0</ixy>
          <ixz>0</ixz>
          <iyy>0.00398967</iyy>
          <iyz>0</iyz>
          <izz>0.00061837</izz>
        </inertia>
      </inertial>

      <collision name='Right_gimbal_collision'>
        <pose>0 0 0 1.57 -0 0</pose>
        <geometry>
          <mesh>
            <scale>0.001 0.001 0.001</scale>
            <uri>model://cmg_robot_description/meshes/right_gimbal_link.STL</uri>
          </mesh>
        </geometry>
        <surface>
          <friction>
            <torsional>
              <coefficient>1</coefficient>
              <use_patch_radius>1</use_patch_radius>
              <patch_radius>0.02</patch_radius>
            </torsional>
            <ode>
              <mu>1</mu>
              <mu2>1</mu2>
            </ode>
          </friction>
          <contact>
            <ode>
              <kp>1e+13</kp>
              <kd>1</kd>
              <max_vel>0.001</max_vel>
              <min_depth>1e-11</min_depth>
            </ode>
          </contact>
        </surface>
      </collision>

      <visual name='Right_gimbal_visual'>
        <pose>0 0 0 1.57 -0 0</pose>
        <geometry>
          <mesh>
            <scale>0.001 0.001 0.001</scale>
            <uri>model://cmg_robot_description/meshes/right_gimbal_link.STL</uri>
          </mesh>
        </geometry>
        <material>
          <script>
            <name>Gazebo/Grey</name>
            <uri>file://media/materials/scripts/gazebo.material</uri>
          </script>
        </material>
      </visual>
      <gravity>1</gravity>
      <self_collide>1</self_collide>
      <gravity>1</gravity>
    </link>

<!-- ######################################################################################### -->

    <joint name='Right_flywheel_joint' type='revolute'>
      <pose relative_to='Right_gimbal'>0 0 0 0 -0 0</pose>
      <parent>Right_gimbal</parent>
      <child>Right_flywheel</child>
      <axis>
        <xyz>0 1 0</xyz>
        <limit>
          <effort>100</effort>
          <velocity>1000</velocity>
          <lower>-1e+16</lower>
          <upper>1e+16</upper>
        </limit>
        <dynamics>
          <spring_reference>0</spring_reference>
          <spring_stiffness>0</spring_stiffness>
        </dynamics>
      </axis>
    </joint>

    <link name='Right_flywheel'>
      <pose relative_to='Right_flywheel_joint'>0 0 0 0 -0 0</pose>
      <inertial>
        <pose>0 0 0 0 -0 0</pose>
        <mass>4</mass>
        <inertia>
          <ixx>0.00595</ixx>
          <ixy>0</ixy>
          <ixz>0</ixz>
          <iyy>0.0113</iyy>
          <iyz>0</iyz>
          <izz>0.00595</izz>
        </inertia>
      </inertial>

      <collision name='Right_flywheel_collision'>
        <pose>0 0 0 0 -0 0</pose>
        <geometry>
          <mesh>
            <scale>0.001 0.001 0.001</scale>
            <uri>model://cmg_robot_description/meshes/right_flywheel_link.STL</uri>
          </mesh>
        </geometry>
        <surface>
          <contact>
            <ode>
              <kp>1e+13</kp>
              <kd>1</kd>
              <max_vel>0.001</max_vel>
              <min_depth>1e-11</min_depth>
            </ode>
          </contact>
          <friction>
            <ode>
              <mu>1</mu>
              <mu2>1</mu2>
            </ode>
          </friction>
        </surface>
      </collision>

      <visual name='Right_flywheel_visual'>
        <pose>0 0 0 0 -0 0</pose>
        <geometry>
          <mesh>
            <scale>0.001 0.001 0.001</scale>
            <uri>model://cmg_robot_description/meshes/right_flywheel_link.STL</uri>
          </mesh>
        </geometry>
        <material>
          <script>
            <name>Gazebo/White</name>
            <uri>file://media/materials/scripts/gazebo.material</uri>
          </script>
        </material>
      </visual>
      <gravity>1</gravity>
      <gravity>1</gravity>
    </link>

<!-- ######################################################################################### -->

    <joint name='hip_roll_joint' type='revolute'>
      <pose relative_to='cmg'>0 0 0.893646 0 -0 0</pose>
      <parent>cmg</parent>
      <child>hip_link</child>
      <axis>
        <xyz>1 0 0</xyz>
        <limit>
          <lower>-0.785</lower>
          <upper>0.785</upper>
          <effort>100</effort>
          <velocity>1000</velocity>
        </limit>
        <dynamics>
          <spring_reference>0</spring_reference>
          <spring_stiffness>0</spring_stiffness>
        </dynamics>
      </axis>
    </joint>

    <link name='hip_link'>
      <pose relative_to='hip_roll_joint'>0 0 0 0 -0 0</pose>
      <inertial>
        <pose>0 0 0.011176 3.14 -0 0</pose>
        <mass>3.325</mass>
        <inertia>
          <ixx>0.00620819</ixx>
          <ixy>0.00039649</ixy>
          <ixz>-0.000685512</ixz>
          <iyy>0.00655491</iyy>
          <iyz>-0.00065852</iyz>
          <izz>0.00677363</izz>
        </inertia>
      </inertial>

      <collision name='hip_link_collision'>
        <pose>-0.042455 0 0 3.14 -0 0</pose>
        <geometry>
          <mesh>
            <scale>0.001 0.001 0.001</scale>
            <uri>model://cmg_robot_description/meshes/hip_link.STL</uri>
          </mesh>
        </geometry>
        <surface>
          <contact>
            <ode>
              <kp>1e+13</kp>
              <kd>1</kd>
              <max_vel>0.001</max_vel>
              <min_depth>1e-11</min_depth>
            </ode>
          </contact>
          <friction>
            <ode>
              <mu>1</mu>
              <mu2>1</mu2>
            </ode>
          </friction>
        </surface>
      </collision>

      <visual name='hip_link_visual'>
        <pose>-0.042455 0 0 3.14 -0 0</pose>
        <geometry>
          <mesh>
            <scale>0.001 0.001 0.001</scale>
            <uri>model://cmg_robot_description/meshes/hip_link.STL</uri>
          </mesh>
        </geometry>
        <material>
          <script>
            <name>Gazebo/Grey</name>
            <uri>file://media/materials/scripts/gazebo.material</uri>
          </script>
        </material>
      </visual>
      <gravity>1</gravity>
      <gravity>1</gravity>
    </link>

<!-- ######################################################################################### -->

    <joint name='hip_pitch_joint' type='revolute'>
      <pose relative_to='hip_link'>0 0 0 0 -0 0</pose>
      <parent>hip_link</parent>
      <child>hip_to_knee_link</child>
      <axis>
        <xyz>0 1 0</xyz>
        <limit>
          <lower>-0.785</lower>
          <upper>0.785</upper>
          <effort>100</effort>
          <velocity>1000</velocity>
        </limit>
        <dynamics>
          <spring_reference>0</spring_reference>
          <spring_stiffness>0</spring_stiffness>
        </dynamics>
      </axis>
    </joint>

    <link name='hip_to_knee_link'>
      <pose relative_to='hip_pitch_joint'>0 0 0 0 -0 0</pose>
      <inertial>
        <pose>0 0 -0.14958 3.14 -0 0</pose>
        <mass>2.175</mass>
        <inertia>
          <ixx>0.00717572</ixx>
          <ixy>8.6944e-05</ixy>
          <ixz>0.000249192</ixz>
          <iyy>0.00660955</iyy>
          <iyz>-0.000206119</iyz>
          <izz>0.00245839</izz>
        </inertia>
      </inertial>

      <collision name='hip_to_knee_link_collision'>
        <pose>0 0.0665 0 3.14 -0 0</pose>
        <geometry>
          <mesh>
            <scale>0.001 0.001 0.001</scale>
            <uri>model://cmg_robot_description/meshes/hip_to_knee_link.STL</uri>
          </mesh>
        </geometry>
        <surface>
          <contact>
            <ode>
              <kp>1e+13</kp>
              <kd>1</kd>
              <max_vel>0.001</max_vel>
              <min_depth>1e-11</min_depth>
            </ode>
          </contact>
          <friction>
            <ode>
              <mu>1</mu>
              <mu2>1</mu2>
            </ode>
          </friction>
        </surface>
      </collision>

      <visual name='hip_to_knee_link_visual'>
        <pose>0 0.0665 0 3.14 -0 0</pose>
        <geometry>
          <mesh>
            <scale>0.001 0.001 0.001</scale>
            <uri>model://cmg_robot_description/meshes/hip_to_knee_link.STL</uri>
          </mesh>
        </geometry>
        <material>
          <script>
            <name>Gazebo/Grey</name>
            <uri>file://media/materials/scripts/gazebo.material</uri>
          </script>
        </material>
      </visual>
      <gravity>1</gravity>
      <gravity>1</gravity>
    </link>

<!-- ######################################################################################### -->

    <joint name='knee_joint' type='revolute'>
      <pose relative_to='hip_to_knee_link'>0 0 -0.28 0 -0 0</pose>
      <parent>hip_to_knee_link</parent>
      <child>knee_ankle_link</child>
      <axis>
        <xyz>0 1 0</xyz>
        <limit>
          <lower>-0.785</lower>
          <upper>0.785</upper>
          <effort>100</effort>
          <velocity>1000</velocity>
        </limit>
        <dynamics>
          <spring_reference>0</spring_reference>
          <spring_stiffness>0</spring_stiffness>
        </dynamics>
      </axis>
    </joint>

    <link name='knee_ankle_link'>
      <pose relative_to='knee_joint'>0 0 0 0 -0 0</pose>
      <inertial>
        <pose>0 0 -0.12016 3.14 -0 0</pose>
        <mass>1.231</mass>
        <inertia>
          <ixx>0.00885931</ixx>
          <ixy>0.000111937</ixy>
          <ixz>0.000678647</ixz>
          <iyy>0.00834396</iyy>
          <iyz>-0.000413906</iyz>
          <izz>0.00207789</izz>
        </inertia>
      </inertial>

      <collision name='knee_ankle_link_collision'>
        <pose>4.5e-05 -0.059 0 3.14 -0 0</pose>
        <geometry>
          <mesh>
            <scale>0.001 0.001 0.001</scale>
            <uri>model://cmg_robot_description/meshes/knee_to_ankle_pitch_link.STL</uri>
          </mesh>
        </geometry>
        <surface>
          <contact>
            <ode>
              <kp>1e+13</kp>
              <kd>1</kd>
              <max_vel>0.001</max_vel>
              <min_depth>1e-11</min_depth>
            </ode>
          </contact>
          <friction>
            <ode>
              <mu>1</mu>
              <mu2>1</mu2>
            </ode>
          </friction>
        </surface>
      </collision>

      <visual name='knee_ankle_link_visual'>
        <pose>4.5e-05 -0.059 0 3.14 -0 0</pose>
        <geometry>
          <mesh>
            <scale>0.001 0.001 0.001</scale>
            <uri>model://cmg_robot_description/meshes/knee_to_ankle_pitch_link.STL</uri>
          </mesh>
        </geometry>
        <material>
          <script>
            <name>Gazebo/Grey</name>
            <uri>file://media/materials/scripts/gazebo.material</uri>
          </script>
        </material>
      </visual>
      <gravity>1</gravity>
      <gravity>1</gravity>
    </link>

<!-- ######################################################################################### -->

    <joint name='ankle_pitch_joint' type='revolute'>
      <pose relative_to='knee_ankle_link'>0 0 -0.279942 0 -0 0</pose>
      <parent>knee_ankle_link</parent>
      <child>ankle_pitch_roll_link</child>
      <axis>
        <xyz>0 1 0</xyz>
        <limit>
          <lower>-0.785</lower>
          <upper>0.785</upper>
          <effort>100</effort>
          <velocity>1000</velocity>
        </limit>
        <dynamics>
          <spring_reference>0</spring_reference>
          <spring_stiffness>0</spring_stiffness>
        </dynamics>
      </axis>
    </joint>
    
    <link name='ankle_pitch_roll_link'>
      <pose relative_to='ankle_pitch_joint'>0 0 0 0 -0 0</pose>
      <inertial>
        <pose>0 0 -0.006827 3.14 -0 0</pose>
        <mass>2.386</mass>
        <inertia>
          <ixx>0.00395099</ixx>
          <ixy>0.000238179</ixy>
          <ixz>0.000315902</ixz>
          <iyy>0.00422633</iyy>
          <iyz>0.000351372</iyz>
          <izz>0.00463355</izz>
        </inertia>
      </inertial>

      <collision name='ankle_pitch_roll_link_collision'>
        <pose>0 0 0 3.14 -0 0</pose>
        <geometry>
          <mesh>
            <scale>0.001 0.001 0.001</scale>
            <uri>model://cmg_robot_description/meshes/ankle_roll_link.STL</uri>
          </mesh>
        </geometry>
        <surface>
          <contact>
            <ode>
              <kp>1e+13</kp>
              <kd>1</kd>
              <max_vel>0.001</max_vel>
              <min_depth>1e-11</min_depth>
            </ode>
          </contact>
          <friction>
            <ode>
              <mu>1</mu>
              <mu2>1</mu2>
            </ode>
          </friction>
        </surface>
      </collision>

      <visual name='ankle_pitch_roll_link_visual'>
        <pose>0 0 0 3.14 -0 0</pose>
        <geometry>
          <mesh>
            <scale>0.001 0.001 0.001</scale>
            <uri>model://cmg_robot_description/meshes/ankle_roll_link.STL</uri>
          </mesh>
        </geometry>
        <material>
          <script>
            <name>Gazebo/Grey</name>
            <uri>file://media/materials/scripts/gazebo.material</uri>
          </script>
        </material>
      </visual>
      <gravity>1</gravity>
      <gravity>1</gravity>
    </link>

<!-- ######################################################################################### -->

    <joint name='ankle_roll_joint' type='revolute'>
      <pose relative_to='ankle_pitch_roll_link'>0 0 0 0 -0 0</pose>
      <parent>ankle_pitch_roll_link</parent>
      <child>ankle_roll_yaw_link</child>
      <axis>
        <xyz>1 0 0</xyz>
        <limit>
          <lower>-0.785</lower>
          <upper>0.785</upper>
          <effort>100</effort>
          <velocity>1000</velocity>
        </limit>
        <dynamics>
          <spring_reference>0</spring_reference>
          <spring_stiffness>0</spring_stiffness>
        </dynamics>
      </axis>
    </joint>

    <link name='ankle_roll_yaw_link'>
      <pose relative_to='ankle_roll_joint'>0 0 0 0 -0 0</pose>
      <inertial>
        <pose>0 0 -0.093558 1.57 -0 1.57</pose>
        <mass>1.325</mass>
        <inertia>
          <ixx>0.00449115</ixx>
          <ixy>5.564e-06</ixy>
          <ixz>3.285e-06</ixz>
          <iyy>0.00263397</iyy>
          <iyz>0.000397982</iyz>
          <izz>0.00235645</izz>
        </inertia>
      </inertial>

      <collision name='ankle_roll_yaw_link_collision'>
        <pose>0.0825 0 0 3.14 -0 0</pose>
        <geometry>
          <mesh>
            <scale>0.001 0.001 0.001</scale>
            <uri>model://cmg_robot_description/meshes/ankle_yaw_link.STL</uri>
          </mesh>
        </geometry>
        <surface>
          <contact>
            <ode>
              <kp>1e+13</kp>
              <kd>1</kd>
              <max_vel>0.001</max_vel>
              <min_depth>1e-11</min_depth>
            </ode>
          </contact>
          <friction>
            <ode>
              <mu>1</mu>
              <mu2>1</mu2>
            </ode>
          </friction>
        </surface>
      </collision>

      <visual name='ankle_roll_yaw_link_visual'>
        <pose>0.0825 0 0 3.14 -0 0</pose>
        <geometry>
          <mesh>
            <scale>0.001 0.001 0.001</scale>
            <uri>model://cmg_robot_description/meshes/ankle_yaw_link.STL</uri>
          </mesh>
        </geometry>
        <material>
          <script>
            <name>Gazebo/Grey</name>
            <uri>file://media/materials/scripts/gazebo.material</uri>
          </script>
        </material>
      </visual>
      <gravity>1</gravity>
      <gravity>1</gravity>
    </link>

<!-- ######################################################################################### -->

    <joint name='ankle_yaw_joint' type='revolute'>
      <pose relative_to='ankle_roll_yaw_link'>0 0 -0.1675 0 -0 0</pose>
      <parent>ankle_roll_yaw_link</parent>
      <child>ankle_to_wheel_link</child>
      <axis>
        <xyz>0 0 1</xyz>
        <limit>
          <lower>-0.785</lower>
          <upper>0.785</upper>
          <effort>100</effort>
          <velocity>1000</velocity>
        </limit>
        <dynamics>
          <spring_reference>0</spring_reference>
          <spring_stiffness>0</spring_stiffness>
        </dynamics>
      </axis>
    </joint>

    <link name='ankle_to_wheel_link'>
      <pose relative_to='ankle_yaw_joint'>0 0 0 0 -0 0</pose>
      <inertial>
        <pose>0 0 0 0 -0 0</pose>
        <mass>0.758</mass>
        <inertia>
          <ixx>0.00229818</ixx>
          <ixy>0</ixy>
          <ixz>0</ixz>
          <iyy>0.00112164</iyy>
          <iyz>0</iyz>
          <izz>0.00148296</izz>
        </inertia>
      </inertial>

      <collision name='ankle_to_wheel_link_collision'>
        <pose>0 0 -0.09 0 -0 0</pose>
        <geometry>
          <mesh>
            <scale>0.001 0.001 0.001</scale>
            <uri>model://cmg_robot_description/meshes/ankle_to_wheel_link.STL</uri>
          </mesh>
        </geometry>
        <surface>
          <contact>
            <ode>
              <kp>1e+13</kp>
              <kd>1</kd>
              <max_vel>0.001</max_vel>
              <min_depth>1e-11</min_depth>
            </ode>
          </contact>
          <friction>
            <ode>
              <mu>1</mu>
              <mu2>1</mu2>
            </ode>
          </friction>
        </surface>
      </collision>

      <visual name='ankle_to_wheel_link_visual'>
        <pose>0 0 -0.09 0 -0 0</pose>
        <geometry>
          <mesh>
            <scale>0.001 0.001 0.001</scale>
            <uri>model://cmg_robot_description/meshes/ankle_to_wheel_link.STL</uri>
          </mesh>
        </geometry>
        <material>
          <script>
            <name>Gazebo/Grey</name>
            <uri>file://media/materials/scripts/gazebo.material</uri>
          </script>
        </material>
      </visual>
      <gravity>1</gravity>
      <gravity>1</gravity>
    </link>

<!-- ######################################################################################### -->

    <joint name='wheel_joint' type='revolute'>
      <pose relative_to='ankle_to_wheel_link'>0 0 -0.09 0 -0 0</pose>
      <parent>ankle_to_wheel_link</parent>
      <child>wheel_link</child>
      <axis>
        <xyz>0 1 0</xyz>
        <limit>
          <effort>100</effort>
          <velocity>1000</velocity>
          <lower>-1e+16</lower>
          <upper>1e+16</upper>
        </limit>
        <dynamics>
          <spring_reference>0</spring_reference>
          <spring_stiffness>0</spring_stiffness>
        </dynamics>
      </axis>
    </joint>
    
    <link name='wheel_link'>
      <pose relative_to='wheel_joint'>0 0 0 0 -0 0</pose>
      <inertial>
        <pose>0 0 0 0 -0 0</pose>
        <mass>2</mass>
        <inertia>
          <ixx>0.00362337</ixx>
          <ixy>0</ixy>
          <ixz>0</ixz>
          <iyy>0.00651263</iyy>
          <iyz>0</iyz>
          <izz>0.00362337</izz>
        </inertia>
      </inertial>

      <collision name='wheel_link_collision'>
        <pose>0 0 0 0 -0 1.57</pose>
        <geometry>
          <mesh>
            <scale>0.001 0.001 0.001</scale>
            <uri>model://cmg_robot_description/meshes/wheel_link.STL</uri>
          </mesh>
        </geometry>
        <surface>
          <friction>
            <torsional>
              <coefficient>1</coefficient>
              <use_patch_radius>1</use_patch_radius>
              <patch_radius>0.02</patch_radius>
            </torsional>
            <ode>
              <mu>1</mu>
              <mu2>1</mu2>
            </ode>
          </friction>
          <contact>
            <ode>
              <kp>1e+13</kp>
              <kd>1</kd>
              <max_vel>0.001</max_vel>
              <min_depth>1e-11</min_depth>
            </ode>
          </contact>
        </surface>
      </collision>

      <visual name='wheel_link_visual'>
        <pose>0 0 0 0 -0 1.57</pose>
        <geometry>
          <mesh>
            <scale>0.001 0.001 0.001</scale>
            <uri>model://cmg_robot_description/meshes/wheel_link.STL</uri>
          </mesh>
        </geometry>
        <material>
          <script>
            <name>Gazebo/White</name>
            <uri>file://media/materials/scripts/gazebo.material</uri>
          </script>
        </material>
      </visual>
      <gravity>1</gravity>
    </link>

<!-- ######################################################################################### -->

    <plugin name='gazebo_ros_control' filename='libgazebo_ros_control.so'/>
        <!-- <controlPeriod>0.001</controlPeriod>
        <robotNamespace>/wheeled_inverted_pendulum</robotNamespace>
        <jointName>Left_flywheel_joint, Right_flywheel_joint, Left_gimbal_joint, Right_gimbal_joint, hip_roll_joint, hip_pitch_joint, knee_joint, ankle_pitch_joint, ankle_roll_joint, ankle_yaw_joint, wheel_joint</jointName>
        <robotSimType>gazebo_ros_control/DefaultRobotHWSim</robotSimType>
        <legacyModeNS>1</legacyModeNS>
    </plugin> -->

    <static>0</static>

    <!-- <transmission name="Left_flywheel_trans">
            <type>transmission_interface/SimpleTransmission</type>
            <joint name="Left_flywheel_joint" >
                <hardwareInterface>hardware_interface/VelocityJointInterface</hardwareInterface>
            </joint>
            <actuator name="Left_flywheel_motor">
                <hardwareInterface>hardware_interface/VelocityJointInterface</hardwareInterface>
                <mechanicalReduction>1</mechanicalReduction>
            </actuator>
    </transmission>

    <transmission name="Left_gimbal_trans">
            <type>transmission_interface/SimpleTransmission</type>
            <joint name="Left_gimbal_joint" >
                <hardwareInterface>hardware_interface/EffortJointInterface</hardwareInterface>
            </joint>
            <actuator name="Left_gimbal_motor">
                <hardwareInterface>hardware_interface/EffortJointInterface</hardwareInterface>
                <mechanicalReduction>1</mechanicalReduction>
            </actuator>
    </transmission>


    <transmission name="Right_flywheel_trans">
            <type>transmission_interface/SimpleTransmission</type>
            <joint name="Right_flywheel_joint" >
                <hardwareInterface>hardware_interface/VelocityJointInterface</hardwareInterface>
            </joint>
            <actuator name="Right_flywheel_motor">
                <hardwareInterface>hardware_interface/VelocityJointInterface</hardwareInterface>
                <mechanicalReduction>1</mechanicalReduction>
            </actuator>
    </transmission>

    <transmission name="Right_gimbal_trans">
            <type>transmission_interface/SimpleTransmission</type>
            <joint name="Right_gimbal_joint" >
                <hardwareInterface>hardware_interface/EffortJointInterface</hardwareInterface>
            </joint>
            <actuator name="Right_gimbal_motor">
                <hardwareInterface>hardware_interface/EffortJointInterface</hardwareInterface>
                <mechanicalReduction>1</mechanicalReduction>
            </actuator>
    </transmission>


    <transmission name="hip_roll_trans">
            <type>transmission_interface/SimpleTransmission</type>
            <joint name="hip_roll_joint" >
                <hardwareInterface>hardware_interface/PositionJointInterface</hardwareInterface>
            </joint>
            <actuator name="hip_roll_motor">
                <hardwareInterface>hardware_interface/PositionJointInterface</hardwareInterface>
                <mechanicalReduction>1</mechanicalReduction>
            </actuator>
    </transmission>

    <transmission name="hip_pitch_trans">
            <type>transmission_interface/SimpleTransmission</type>
            <joint name="hip_pitch_joint" >
                <hardwareInterface>hardware_interface/PositionJointInterface</hardwareInterface>
            </joint>
            <actuator name="hip_pitch_motor">
                <hardwareInterface>hardware_interface/PositionJointInterface</hardwareInterface>
                <mechanicalReduction>1</mechanicalReduction>
            </actuator>
    </transmission>


    <transmission name="knee_trans">
            <type>transmission_interface/SimpleTransmission</type>
            <joint name="knee_joint" >
                <hardwareInterface>hardware_interface/PositionJointInterface</hardwareInterface>
            </joint>
            <actuator name="knee_motor">
                <hardwareInterface>hardware_interface/PositionJointInterface</hardwareInterface>
                <mechanicalReduction>1</mechanicalReduction>
            </actuator>
    </transmission>

    <transmission name="ankle_pitch_trans">
            <type>transmission_interface/SimpleTransmission</type>
            <joint name="ankle_pitch_joint" >
                <hardwareInterface>hardware_interface/PositionJointInterface</hardwareInterface>
            </joint>
            <actuator name="ankle_pitch_motor">
                <hardwareInterface>hardware_interface/PositionJointInterface</hardwareInterface>
                <mechanicalReduction>1</mechanicalReduction>
            </actuator>
    </transmission>

    <transmission name="ankle_roll_trans">
            <type>transmission_interface/SimpleTransmission</type>
            <joint name="ankle_roll_joint" >
                <hardwareInterface>hardware_interface/PositionJointInterface</hardwareInterface>
            </joint>
            <actuator name="ankle_roll_motor">
                <hardwareInterface>hardware_interface/PositionJointInterface</hardwareInterface>
                <mechanicalReduction>1</mechanicalReduction>
            </actuator>
    </transmission>

    <transmission name="ankle_yaw_trans">
            <type>transmission_interface/SimpleTransmission</type>
            <joint name="ankle_yaw_joint" >
                <hardwareInterface>hardware_interface/PositionJointInterface</hardwareInterface>
            </joint>
            <actuator name="ankle_yaw_motor">
                <hardwareInterface>hardware_interface/PositionJointInterface</hardwareInterface>
                <mechanicalReduction>1</mechanicalReduction>
            </actuator>
    </transmission>

    <transmission name="wheel_trans">
            <type>transmission_interface/SimpleTransmission</type>
            <joint name="wheel_joint" >
                <hardwareInterface>hardware_interface/EffortJointInterface</hardwareInterface>
            </joint>
            <actuator name="wheel_motor">
                <hardwareInterface>hardware_interface/EffortJointInterface</hardwareInterface>
                <mechanicalReduction>1</mechanicalReduction>
            </actuator>
    </transmission> -->
  </model>   

<!-- ######################################################################################### -->

    
    
</sdf>
